<robot xmlns:xacro="http://ros.org/wiki/xacro">
        <xacro:property name="s1" value="0.85" />
        <xacro:property name="e1" value="40" />

        <xacro:include filename="$(find robotiq_3f_gripper_visualization)/cfg/robotiq-3f-gripper_finger_articulated_macro.xacro" />

        <xacro:macro name="robotiq-3f-gripper_articulated" params="prefix *origin parent">

        <xacro:robotiq-3f-gripper_finger_articulated prefix="${prefix}finger_1_"/>
        <xacro:robotiq-3f-gripper_finger_articulated prefix="${prefix}finger_2_"/>
        <xacro:robotiq-3f-gripper_finger_articulated prefix="${prefix}finger_middle_"/>

		<!-- link list -->
		<link name="${prefix}palm">
			<visual>
				<geometry>
                                        <mesh filename="package://robotiq_3f_gripper_visualization/meshes/robotiq-3f-gripper_articulated/visual/palm.dae" />
				</geometry>
				<material name="gray">
					<color rgba="0.2 0.2 0.2 1"/>
				</material>
			</visual>
			<collision>
				<geometry>
                                        <mesh filename="package://robotiq_3f_gripper_visualization/meshes/robotiq-3f-gripper_articulated/collision/palm.STL" />
				</geometry>
				<material name="yellow">
					<color rgba="0 1 1 1"/>
				</material>
			</collision>
		</link>

	    <gazebo reference="${prefix}palm">
      		<mu1>1.1</mu1>
      		<mu2>1.1</mu2>
    	</gazebo>

        <inertial>
            <origin xyz="0 0 0" rpy="0 0 0"/>
            <mass value="1.3"/>
            <inertia ixx="0.006012" ixy="0.000079" ixz="-0.00024" iyy="0.012892" iyz="0" izz="0.002435" />
        </inertial>
		<!-- end of link list -->

		<!-- joint list -->
		<joint name="${prefix}palm_finger_1_joint" type="revolute">
			<parent link="${prefix}palm"/>
			<child link="${prefix}finger_1_link_0"/>
			<axis xyz="0 1 0"/>
			<origin xyz="-0.0455 0.0214 0.036" rpy="0 3.1416 -1.57"/>
                        <limit lower="-0.1784" upper="0.192" effort="10" velocity="${s1}"/>
		</joint>
		<joint name="${prefix}palm_finger_2_joint" type="revolute">
			<parent link="${prefix}palm"/>
			<child link="${prefix}finger_2_link_0"/>
			<axis xyz="0 1 0"/>
			<origin xyz="-0.0455 0.0214 -0.036" rpy="0 3.1416 -1.57"/>
                        <limit lower="-0.192" upper="0.1784" effort="10" velocity="${s1}"/>
		</joint>
		<joint name="${prefix}palm_finger_middle_joint" type="fixed">
			<parent link="${prefix}palm"/>
			<child link="${prefix}finger_middle_link_0"/>
			<axis xyz="0 0 1"/>
			<origin xyz="0.0455 0.0214 0" rpy="0 0 1.57"/>
		</joint>
		<joint name="${prefix}robotiq_hand_joint" type="fixed">
      		<xacro:insert_block name="origin"/>
      		<parent link="${parent}"/>
      		<child link="${prefix}palm"/>
    	</joint>
        <!-- end of joint list -->

	<!-- Palm transmission macro -->
    <transmission name="${prefix}palm_finger_1_trans">
      <type>transmission_interface/SimpleTransmission</type>
      <joint name="${prefix}palm_finger_1_joint">
        <hardwareInterface>hardware_interface/EffortJointInterface</hardwareInterface>
      </joint>
      <actuator name="${prefix}palm_finger_1_motor">
        <mechanicalReduction>1</mechanicalReduction>
      </actuator>
    </transmission>
    <transmission name="${prefix}palm_finger_2_trans">
      <type>transmission_interface/SimpleTransmission</type>
      <joint name="${prefix}palm_finger_2_joint">
        <hardwareInterface>hardware_interface/EffortJointInterface</hardwareInterface>
      </joint>
      <actuator name="${prefix}palm_finger_2_motor">
        <mechanicalReduction>1</mechanicalReduction>
      </actuator>
    </transmission>

	<!-- Finger 1 transmission macro -->
    <transmission name="${prefix}finger_1_trans_1">
      <type>transmission_interface/SimpleTransmission</type>
      <joint name="${prefix}finger_1_joint_1">
        <hardwareInterface>hardware_interface/EffortJointInterface</hardwareInterface>
      </joint>
      <actuator name="${prefix}finger_1_motor_1">
        <mechanicalReduction>1</mechanicalReduction>
      </actuator>
    </transmission>
    <transmission name="${prefix}finger_1_trans_2">
      <type>transmission_interface/SimpleTransmission</type>
      <joint name="${prefix}finger_1_joint_2">
        <hardwareInterface>hardware_interface/EffortJointInterface</hardwareInterface>
      </joint>
      <actuator name="${prefix}finger_1_motor_2">
        <mechanicalReduction>1</mechanicalReduction>
      </actuator>
    </transmission>
    <transmission name="${prefix}finger_1_trans_3">
      <type>transmission_interface/SimpleTransmission</type>
      <joint name="${prefix}finger_1_joint_3">
        <hardwareInterface>hardware_interface/EffortJointInterface</hardwareInterface>
      </joint>
      <actuator name="${prefix}finger_1_motor_3">
        <mechanicalReduction>1</mechanicalReduction>
      </actuator>
    </transmission>

	<!-- Finger 2 transmission macro -->
    <transmission name="${prefix}finger_2_trans_1">
      <type>transmission_interface/SimpleTransmission</type>
      <joint name="${prefix}finger_2_joint_1">
        <hardwareInterface>hardware_interface/EffortJointInterface</hardwareInterface>
      </joint>
      <actuator name="${prefix}finger_2_motor_1">
        <mechanicalReduction>1</mechanicalReduction>
      </actuator>
    </transmission>
    <transmission name="${prefix}finger_2_trans_2">
      <type>transmission_interface/SimpleTransmission</type>
      <joint name="${prefix}finger_2_joint_2">
        <hardwareInterface>hardware_interface/EffortJointInterface</hardwareInterface>
      </joint>
      <actuator name="${prefix}finger_2_motor_2">
        <mechanicalReduction>1</mechanicalReduction>
      </actuator>
    </transmission>
    <transmission name="${prefix}finger_2_trans_3">
      <type>transmission_interface/SimpleTransmission</type>
      <joint name="${prefix}finger_2_joint_3">
        <hardwareInterface>hardware_interface/EffortJointInterface</hardwareInterface>
      </joint>
      <actuator name="${prefix}finger_2_motor_3">
        <mechanicalReduction>1</mechanicalReduction>
      </actuator>
    </transmission>

	<!-- Finger middle transmission macro -->
    <transmission name="${prefix}finger_middle_trans_1">
      <type>transmission_interface/SimpleTransmission</type>
      <joint name="${prefix}finger_middle_joint_1">
        <hardwareInterface>hardware_interface/EffortJointInterface</hardwareInterface>
      </joint>
      <actuator name="${prefix}finger_middle_motor_1">
        <mechanicalReduction>1</mechanicalReduction>
      </actuator>
    </transmission>
    <transmission name="${prefix}finger_middle_trans_2">
      <type>transmission_interface/SimpleTransmission</type>
      <joint name="${prefix}finger_middle_joint_2">
        <hardwareInterface>hardware_interface/EffortJointInterface</hardwareInterface>
      </joint>
      <actuator name="${prefix}finger_middle_motor_2">
        <mechanicalReduction>1</mechanicalReduction>
      </actuator>
    </transmission>
    <transmission name="${prefix}finger_middle_trans_3">
      <type>transmission_interface/SimpleTransmission</type>
      <joint name="${prefix}finger_middle_joint_3">
        <hardwareInterface>hardware_interface/EffortJointInterface</hardwareInterface>
      </joint>
      <actuator name="${prefix}finger_middle_motor_3">
        <mechanicalReduction>1</mechanicalReduction>
      </actuator>
    </transmission>

	<!-- Configure self collision properties per link -->
<!--  TODO: When active, model begins oscillating
    <gazebo reference="${prefix}palm">
      <selfCollide>true</selfCollide>
    </gazebo>
    <gazebo reference="${prefix}finger_1_link_0">
      <selfCollide>true</selfCollide>
    </gazebo>
    <gazebo reference="${prefix}finger_1_link_1">
      <selfCollide>true</selfCollide>
    </gazebo>
    <gazebo reference="${prefix}finger_1_link_2">
      <selfCollide>true</selfCollide>
    </gazebo>
    <gazebo reference="${prefix}finger_1_link_3">
      <selfCollide>true</selfCollide>
    </gazebo>
    <gazebo reference="${prefix}finger_2_link_0">
      <selfCollide>true</selfCollide>
    </gazebo>
    <gazebo reference="${prefix}finger_2_link_1">
      <selfCollide>true</selfCollide>
    </gazebo>
    <gazebo reference="${prefix}finger_2_link_2">
      <selfCollide>true</selfCollide>
    </gazebo>
    <gazebo reference="${prefix}finger_2_link_3">
      <selfCollide>true</selfCollide>
    </gazebo>
    <gazebo reference="${prefix}finger_middle_link_1">
      <selfCollide>true</selfCollide>
    </gazebo>
    <gazebo reference="${prefix}finger_middle_link_2">
      <selfCollide>true</selfCollide>
    </gazebo>
    <gazebo reference="${prefix}finger_middle_link_3">
      <selfCollide>true</selfCollide>
    </gazebo>
-->
    <gazebo reference="${prefix}finger_1_link_3">
      <collision>
        <surface>
          <friction>
            <torsional>
                <patch_radius>0.1</patch_radius>
            </torsional>
            <ode>
                <mu>100</mu>
                <mu2>100</mu2>
            </ode>
          </friction>
          <contact>
            <ode>
              <soft_cfm>0.001</soft_cfm>
              <min_depth>0.003</min_depth>
              <max_vel>0.1</max_vel>
            </ode>
          </contact>
        </surface>
      </collision>
    </gazebo>
    <gazebo reference="${prefix}finger_2_link_3">
      <collision>
        <surface>
          <friction>
            <torsional>
                <patch_radius>0.1</patch_radius>
            </torsional>
            <ode>
                <mu>100</mu>
                <mu2>100</mu2>
            </ode>
          </friction>
          <contact>
            <ode>
              <soft_cfm>0.001</soft_cfm>
              <min_depth>0.003</min_depth>
              <max_vel>0.1</max_vel>
            </ode>
          </contact>
        </surface>
      </collision>
    </gazebo>
    <gazebo reference="${prefix}finger_middle_link_3">
      <collision>
        <surface>
          <friction>
            <torsional>
                <patch_radius>0.1</patch_radius>
            </torsional>
            <ode>
                <mu>100</mu>
                <mu2>100</mu2>
            </ode>
          </friction>
          <contact>
            <ode>
              <soft_cfm>0.001</soft_cfm>
              <min_depth>0.003</min_depth>
              <max_vel>0.1</max_vel>
            </ode>
          </contact>
        </surface>
      </collision>
    </gazebo>
	</xacro:macro>
</robot>
